Workbook

Sheet Tracker
A1: DSA PREPARATION TRACKER — AGODA EM LOOP
A2: FILL IN the yellow columns: Status, Time, Solved Unaided?, Needs Re-do, Re-do Done, Confidence, Notes. Columns A-J are reference. Descriptions are paraphrased summaries — read the full problem statement on the platform before solving.
A3: # | B3: Day | C3: Block | D3: Pattern | E3: Problem | F3: Description | G3: Sample Input | H3: Expected Output | I3: Difficulty | J3: Priority | K3: Status | L3: Time (min) | M3: Solved Unaided? | N3: Needs Re-do | O3: Re-do Done | P3: Confidence (1-5) | Q3: Key Insight / Notes
A4: 0 | B4: 1 | C4: 1 | D4: (example row — delete me) | E4: Two Sum | F4: Return indices of the two numbers adding to target. | G4: nums = [2,7,11,15], target = 9 | H4: [0,1] | I4: Easy | J4: Core | K4: Done | L4: 12 | M4: Yes | N4: No | P4: 4 | Q4: Hash map of complement; single pass.
A5: 1 | B5: 1 | C5: 1 | D5: Hash Map & Arrays | E5: Two Sum | F5: Return the indices of the two numbers in the array that add up to the target. Exactly one valid pair exists. | G5: nums = [2,7,11,15], target = 9 | H5: [0,1] | I5: Easy | J5: Core | K5: Done
A6: 2 | B6: 1 | C6: 1 | D6: Hash Map & Arrays | E6: Contains Duplicate | F6: Return true if any value appears at least twice in the array. | G6: nums = [1,2,3,1] | H6: true | I6: Easy | J6: Core | K6: Done
A7: 3 | B7: 1 | C7: 1 | D7: Hash Map & Arrays | E7: Valid Anagram | F7: Return true if the second string is a rearrangement of the characters of the first. | G7: s = "anagram", t = "nagaram" | H7: true | I7: Easy | J7: Core | K7: Done
A8: 4 | B8: 1 | C8: 1 | D8: Hash Map & Arrays | E8: Group Anagrams | F8: Group all strings that are anagrams of one another into sublists. Order of groups does not matter. | G8: strs = ["eat","tea","tan","ate","nat","bat"] | H8: [["eat","tea","ate"],["tan","nat"],["bat"]] | I8: Medium | J8: Core | K8: Done
A9: 5 | B9: 1 | C9: 1 | D9: Hash Map & Arrays | E9: Top K Frequent Elements | F9: Return the k most frequently occurring values in the array. | G9: nums = [1,1,1,2,2,3], k = 2 | H9: [1,2] | I9: Medium | J9: Core | K9: Done
A10: 6 | B10: 1 | C10: 1 | D10: Hash Map & Arrays | E10: Product of Array Except Self | F10: For each index, return the product of every other element. No division allowed; aim for O(n). | G10: nums = [1,2,3,4] | H10: [24,12,8,6] | I10: Medium | J10: Core | K10: Done
A11: 7 | B11: 1 | C11: 1 | D11: Hash Map & Arrays | E11: Longest Consecutive Sequence | F11: Return the length of the longest run of consecutive integers present in the array. Target O(n). | G11: nums = [100,4,200,1,3,2] | H11: 4 | I11: Medium | J11: Core | K11: Done
A12: 8 | B12: 1 | C12: 1 | D12: Hash Map & Arrays | E12: Subarray Sum Equals K | F12: Count the contiguous subarrays whose elements sum to k. Prefix-sum plus hash map. | G12: nums = [1,1,1], k = 2 | H12: 2 | I12: Medium | J12: Core
A13: 9 | B13: 1 | C13: 2 | D13: Two Pointers | E13: Valid Palindrome | F13: Ignoring non-alphanumeric characters and case, determine whether the string reads the same forwards and backwards. | G13: s = "A man, a plan, a canal: Panama" | H13: true | I13: Easy | J13: Core | K13: Done
A14: 10 | B14: 1 | C14: 2 | D14: Two Pointers | E14: Two Sum II (Sorted Input) | F14: The array is sorted. Return the 1-indexed positions of the two values summing to the target, using O(1) extra space. | G14: numbers = [2,7,11,15], target = 9 | H14: [1,2] | I14: Medium | J14: Core | K14: Done
A15: 11 | B15: 1 | C15: 2 | D15: Two Pointers | E15: 3Sum | F15: Find all unique triplets in the array that sum to zero. No duplicate triplets in the output. | G15: nums = [-1,0,1,2,-1,-4] | H15: [[-1,-1,2],[-1,0,1]] | I15: Medium | J15: Core | K15: Done
A16: 12 | B16: 1 | C16: 2 | D16: Two Pointers | E16: Container With Most Water | F16: Each value is a vertical line height. Pick two lines that with the x-axis hold the most water. | G16: height = [1,8,6,2,5,4,8,3,7] | H16: 49 | I16: Medium | J16: Core | K16: Done
A17: 13 | B17: 1 | C17: 2 | D17: Two Pointers | E17: Sort Colors | F17: Sort an array containing only 0s, 1s and 2s in a single pass with constant extra space (Dutch national flag). | G17: nums = [2,0,2,1,1,0] | H17: [0,0,1,1,2,2] | I17: Medium | J17: Optional | K17: Done
A18: 14 | B18: 1 | C18: 2 | D18: Two Pointers | E18: Trapping Rain Water | F18: Given an elevation map, compute how much rainwater is trapped between the bars. | G18: height = [0,1,0,2,1,0,1,3,2,1,2,1] | H18: 6 | I18: Hard | J18: Stretch
A19: 15 | B19: 1 | C19: 3 | D19: Sliding Window | E19: Best Time to Buy and Sell Stock | F19: One buy and one sell, buy before sell. Return the maximum achievable profit, or 0. | G19: prices = [7,1,5,3,6,4] | H19: 5 | I19: Easy | J19: Core | K19: Done
A20: 16 | B20: 1 | C20: 3 | D20: Sliding Window | E20: Longest Substring Without Repeating Chars | F20: Return the length of the longest substring containing no repeated character. | G20: s = "abcabcbb" | H20: 3 | I20: Medium | J20: Core | K20: Done
A21: 17 | B21: 2 | C21: 3 | D21: Sliding Window | E21: Longest Repeating Character Replacement | F21: You may change up to k characters. Return the longest substring achievable of a single repeated letter. | G21: s = "AABABBA", k = 1 | H21: 4 | I21: Medium | J21: Core
A22: 18 | B22: 2 | C22: 3 | D22: Sliding Window | E22: Permutation in String | F22: Return true if the second string contains any permutation of the first as a contiguous substring. | G22: s1 = "ab", s2 = "eidbaooo" | H22: true | I22: Medium | J22: Core
A23: 19 | B23: 2 | C23: 3 | D23: Sliding Window | E23: Maximum Average Subarray I | F23: Find the contiguous subarray of exactly length k with the largest average. | G23: nums = [1,12,-5,-6,50,3], k = 4 | H23: 12.75 | I23: Easy | J23: Optional
A24: 20 | B24: 2 | C24: 3 | D24: Sliding Window | E24: Minimum Window Substring | F24: Return the shortest substring of s containing every character of t, including duplicates. | G24: s = "ADOBECODEBANC", t = "ABC" | H24: "BANC" | I24: Hard | J24: Stretch
A25: 21 | B25: 2 | C25: 3 | D25: Sliding Window | E25: Sliding Window Maximum | F25: For every window of size k, report the maximum. Use a monotonic deque for O(n). | G25: nums = [1,3,-1,-3,5,3,6,7], k = 3 | H25: [3,3,5,5,6,7] | I25: Hard | J25: Stretch
A26: 22 | B26: 2 | C26: 4 | D26: Stack | E26: Valid Parentheses | F26: Determine whether the bracket string is correctly opened and closed in the right order. | G26: s = "()[]{}" | H26: true | I26: Easy | J26: Core | K26: Done
A27: 23 | B27: 2 | C27: 4 | D27: Stack | E27: Min Stack | F27: Design a stack supporting push, pop, top and retrieving the minimum, all in O(1). | G27: push(-2); push(0); push(-3); getMin(); pop(); top(); getMin() | H27: -3, then 0, then -2 | I27: Medium | J27: Core | K27: Done
A28: 24 | B28: 2 | C28: 4 | D28: Stack | E28: Evaluate Reverse Polish Notation | F28: Evaluate an arithmetic expression given in postfix notation. | G28: tokens = ["2","1","+","3","*"] | H28: 9 | I28: Medium | J28: Core | K28: Done
A29: 25 | B29: 2 | C29: 4 | D29: Stack | E29: Daily Temperatures | F29: For each day, how many days until a warmer temperature. 0 if none. Monotonic stack. | G29: temperatures = [73,74,75,71,69,72,76,73] | H29: [1,1,4,2,1,1,0,0] | I29: Medium | J29: Core | K29: Done
A30: 26 | B30: 2 | C30: 4 | D30: Stack | E30: Largest Rectangle in Histogram | F30: Find the area of the largest rectangle that fits inside the histogram. | G30: heights = [2,1,5,6,2,3] | H30: 10 | I30: Hard | J30: Stretch
A31: 27 | B31: 2 | C31: 5 | D31: Binary Search | E31: Binary Search | F31: Classic search in a sorted array. Return the index of the target or -1. | G31: nums = [-1,0,3,5,9,12], target = 9 | H31: 4 | I31: Easy | J31: Core | K31: Done
A32: 28 | B32: 2 | C32: 5 | D32: Binary Search | E32: Search a 2D Matrix | F32: Rows are sorted and each row starts after the previous ends. Search the matrix in O(log(m*n)). | G32: matrix = [[1,3,5,7],[10,11,16,20],[23,30,34,60]], target = 3 | H32: true | I32: Medium | J32: Core
A33: 29 | B33: 2 | C33: 5 | D33: Binary Search | E33: Find Minimum in Rotated Sorted Array | F33: A sorted array was rotated at an unknown pivot. Find the minimum in O(log n). | G33: nums = [3,4,5,1,2] | H33: 1 | I33: Medium | J33: Core
A34: 30 | B34: 2 | C34: 5 | D34: Binary Search | E34: Search in Rotated Sorted Array | F34: Search for a target in a rotated sorted array in O(log n). Decide which half is sorted at each step. | G34: nums = [4,5,6,7,0,1,2], target = 0 | H34: 4 | I34: Medium | J34: Core
A35: 31 | B35: 2 | C35: 5 | D35: Binary Search | E35: Koko Eating Bananas | F35: Find the minimum eating speed that finishes all piles within h hours. Binary search on the answer. | G35: piles = [3,6,7,11], h = 8 | H35: 4 | I35: Medium | J35: Core
A36: 32 | B36: 2 | C36: 5 | D36: Binary Search | E36: Median of Two Sorted Arrays | F36: Find the median of two sorted arrays in O(log(min(m,n))). Partition-based binary search. | G36: nums1 = [1,3], nums2 = [2] | H36: 2.00000 | I36: Hard | J36: Stretch
A37: 33 | B37: 3 | C37: 6 | D37: Linked List | E37: Reverse Linked List | F37: Reverse a singly linked list. Know both the iterative and recursive forms. | G37: head = [1,2,3,4,5] | H37: [5,4,3,2,1] | I37: Easy | J37: Core | K37: Done
A38: 34 | B38: 3 | C38: 6 | D38: Linked List | E38: Merge Two Sorted Lists | F38: Merge two sorted linked lists into one sorted list by splicing nodes. | G38: list1 = [1,2,4], list2 = [1,3,4] | H38: [1,1,2,3,4,4] | I38: Easy | J38: Core | K38: Done
A39: 35 | B39: 3 | C39: 6 | D39: Linked List | E39: Linked List Cycle | F39: Detect whether the list contains a cycle using fast and slow pointers. | G39: head = [3,2,0,-4], tail connects to index 1 | H39: true | I39: Easy | J39: Core | K39: Done
A40: 36 | B40: 3 | C40: 6 | D40: Linked List | E40: Remove Nth Node From End | F40: Remove the nth node counted from the end, in a single pass using two offset pointers. | G40: head = [1,2,3,4,5], n = 2 | H40: [1,2,3,5] | I40: Medium | J40: Core | K40: Done
...

Sheet Dashboard
A1: PROGRESS DASHBOARD
A3: OVERALL | D3: BY DAY
A4: Total problems | B4: =COUNTA(Tracker!$E$5:$E$82) -> 78 | D4: Day | E4: Planned | F4: Done | G4: % Done
A5: Completed | B5: =COUNTIF(Tracker!$K$5:$K$82,"Done") -> 31 | D5: 1 | E5: =COUNTIF(Tracker!$B$5:$B$82,$D5) -> 16 | F5: =COUNTIFS(Tracker!$B$5:$B$82,$D5,Tracker!$K$5:$K$82,"Done") -> 14 | G5: =IFERROR(F5/E5,0) -> 0.875
A6: In progress | B6: =COUNTIF(Tracker!$K$5:$K$82,"In Progress") -> 0 | D6: 2 | E6: =COUNTIF(Tracker!$B$5:$B$82,$D6) -> 16 | F6: =COUNTIFS(Tracker!$B$5:$B$82,$D6,Tracker!$K$5:$K$82,"Done") -> 5 | G6: =IFERROR(F6/E6,0) -> 0.3125
A7: Not started | B7: =COUNTA(Tracker!$E$5:$E$82)-COUNTIF(Tracker!$K$5:$K$82,"Done")-COUNTIF(Tracker!$K$5:$K$82,"In Progress")-COUNTIF(Tracker!$K$5:$K$82,"Skipped") -> 47 | D7: 3 | E7: =COUNTIF(Tracker!$B$5:$B$82,$D7) -> 16 | F7: =COUNTIFS(Tracker!$B$5:$B$82,$D7,Tracker!$K$5:$K$82,"Done") -> 12 | G7: =IFERROR(F7/E7,0) -> 0.75
A8: Completion % | B8: =IFERROR(B5/B4,0) -> 0.3974359 | D8: 4 | E8: =COUNTIF(Tracker!$B$5:$B$82,$D8) -> 16 | F8: =COUNTIFS(Tracker!$B$5:$B$82,$D8,Tracker!$K$5:$K$82,"Done") -> 0 | G8: =IFERROR(F8/E8,0) -> 0
A9: Core done | B9: =COUNTIFS(Tracker!$J$5:$J$82,"Core",Tracker!$K$5:$K$82,"Done") -> 28 | D9: 5 | E9: =COUNTIF(Tracker!$B$5:$B$82,$D9) -> 14 | F9: =COUNTIFS(Tracker!$B$5:$B$82,$D9,Tracker!$K$5:$K$82,"Done") -> 0 | G9: =IFERROR(F9/E9,0) -> 0
A10: Core total | B10: =COUNTIF(Tracker!$J$5:$J$82,"Core") -> 59 | D10: TOTAL | E10: =SUM(E5:E9) -> 78 | F10: =SUM(F5:F9) -> 31 | G10: =IFERROR(F10/E10,0) -> 0.3974359
A11: Core completion % | B11: =IFERROR(B9/B10,0) -> 0.47457627
A12: Solved unaided | B12: =COUNTIF(Tracker!$M$5:$M$82,"Yes") -> 0 | D12: BY PATTERN
A13: Unaided rate | B13: =IFERROR(B12/MAX(B5,1),0) -> 0 | D13: Pattern | E13: Planned | F13: Done | G13: % Done
A14: Total time (min) | B14: =SUM(Tracker!$L$5:$L$82) -> 0 | D14: Hash Map & Arrays | E14: =COUNTIF(Tracker!$D$5:$D$82,$D14) -> 8 | F14: =COUNTIFS(Tracker!$D$5:$D$82,$D14,Tracker!$K$5:$K$82,"Done") -> 7 | G14: =IFERROR(F14/E14,0) -> 0.875
A15: Total time (hrs) | B15: =IFERROR(B14/60,0) -> 0 | D15: Two Pointers | E15: =COUNTIF(Tracker!$D$5:$D$82,$D15) -> 6 | F15: =COUNTIFS(Tracker!$D$5:$D$82,$D15,Tracker!$K$5:$K$82,"Done") -> 5 | G15: =IFERROR(F15/E15,0) -> 0.83333333
A16: Avg time per problem | B16: =IFERROR(B14/MAX(B5,1),0) -> 0 | D16: Sliding Window | E16: =COUNTIF(Tracker!$D$5:$D$82,$D16) -> 7 | F16: =COUNTIFS(Tracker!$D$5:$D$82,$D16,Tracker!$K$5:$K$82,"Done") -> 2 | G16: =IFERROR(F16/E16,0) -> 0.28571429
A17: Avg confidence | B17: =IFERROR(AVERAGE(Tracker!$P$5:$P$82),0) -> 0 | D17: Stack | E17: =COUNTIF(Tracker!$D$5:$D$82,$D17) -> 5 | F17: =COUNTIFS(Tracker!$D$5:$D$82,$D17,Tracker!$K$5:$K$82,"Done") -> 4 | G17: =IFERROR(F17/E17,0) -> 0.8
A18: Re-dos outstanding | B18: =COUNTIFS(Tracker!$N$5:$N$82,"Yes",Tracker!$O$5:$O$82,"No")+COUNTIFS(Tracker!$N$5:$N$82,"Yes",Tracker!$O$5:$O$82,"") -> 0 | D18: Binary Search | E18: =COUNTIF(Tracker!$D$5:$D$82,$D18) -> 6 | F18: =COUNTIFS(Tracker!$D$5:$D$82,$D18,Tracker!$K$5:$K$82,"Done") -> 1 | G18: =IFERROR(F18/E18,0) -> 0.16666667
D19: Linked List | E19: =COUNTIF(Tracker!$D$5:$D$82,$D19) -> 6 | F19: =COUNTIFS(Tracker!$D$5:$D$82,$D19,Tracker!$K$5:$K$82,"Done") -> 4 | G19: =IFERROR(F19/E19,0) -> 0.66666667
A20: READINESS GATES | D20: Trees | E20: =COUNTIF(Tracker!$D$5:$D$82,$D20) -> 10 | F20: =COUNTIFS(Tracker!$D$5:$D$82,$D20,Tracker!$K$5:$K$82,"Done") -> 8 | G20: =IFERROR(F20/E20,0) -> 0.8
A21: All Core problems done | B21: =IF(B9>=B10,"READY","NOT YET") -> NOT YET | D21: Heap / Priority Queue | E21: =COUNTIF(Tracker!$D$5:$D$82,$D21) -> 5 | F21: =COUNTIFS(Tracker!$D$5:$D$82,$D21,Tracker!$K$5:$K$82,"Done") -> 0 | G21: =IFERROR(F21/E21,0) -> 0
A22: Unaided rate >= 70% | B22: =IF(B13>=0.7,"READY","NOT YET") -> NOT YET | D22: Graphs | E22: =COUNTIF(Tracker!$D$5:$D$82,$D22) -> 8 | F22: =COUNTIFS(Tracker!$D$5:$D$82,$D22,Tracker!$K$5:$K$82,"Done") -> 0 | G22: =IFERROR(F22/E22,0) -> 0
A23: Avg confidence >= 3.5 | B23: =IF(B17>=3.5,"READY","NOT YET") -> NOT YET | D23: Intervals | E23: =COUNTIF(Tracker!$D$5:$D$82,$D23) -> 5 | F23: =COUNTIFS(Tracker!$D$5:$D$82,$D23,Tracker!$K$5:$K$82,"Done") -> 0 | G23: =IFERROR(F23/E23,0) -> 0
A24: No outstanding re-dos | B24: =IF(B19=0,"READY","NOT YET") -> READY | D24: Dynamic Programming | E24: =COUNTIF(Tracker!$D$5:$D$82,$D24) -> 8 | F24: =COUNTIFS(Tracker!$D$5:$D$82,$D24,Tracker!$K$5:$K$82,"Done") -> 0 | G24: =IFERROR(F24/E24,0) -> 0
D25: Backtracking | E25: =COUNTIF(Tracker!$D$5:$D$82,$D25) -> 4 | F25: =COUNTIFS(Tracker!$D$5:$D$82,$D25,Tracker!$K$5:$K$82,"Done") -> 0 | G25: =IFERROR(F25/E25,0) -> 0
A26: 'Solved unaided' is the metric that matters. A problem you read the solution for is not done — set Needs Re-do = Yes and re-solve it cold before the loop.

Sheet Daily Log
A1: DAILY LOG
A2: Day | B2: Date | C2: Hours Studied | D2: Problems Done | E2: Weakest Pattern Today | F2: Reflection / What to fix tomorrow
A3: 0 | B3: (example) | C3: 2.5 | D3: 14 | E3: Binary search boundaries | F3: Off-by-one on the upper bound repeatedly. Re-drill the template first thing tomorrow.
A4: 1
A5: 2
A6: 3
A7: 4
A8: 5
A9: TOTAL | C9: =SUM(C4:C8) -> 0 | D9: =SUM(D4:D8) -> 0

Sheet Delivery Checklist
A1: INTERVIEW DELIVERY SEQUENCE — REHEARSE UNTIL AUTOMATIC
A2: Step | B2: Action | C2: Habitual? (Y/N)
A3: 1 | B3: Restate the problem and confirm your understanding
A4: 2 | B4: Ask about constraints: input size, value ranges, duplicates, empty input, sorted?
A5: 3 | B5: State the brute-force approach and its time/space complexity
A6: 4 | B6: Describe the optimised approach BEFORE writing code; get agreement
A7: 5 | B7: Code it while narrating your reasoning out loud
A8: 6 | B8: Walk through a worked example manually, including one edge case
A9: 7 | B9: State final time and space complexity unprompted
A10: 8 | B10: Say what you would change for production (validation, guards, testability)
A12: Step 8 is your differentiator as an engineering manager. ICs routinely skip it; interviewers notice.
